<robot name= "wheeltec_gripper" xmlns:xacro="http://www.ros.org/wiki/xacro">
 
 <link name="wheeltec_gripper_base_link"/>

  <joint name="wheeltec_gripper_base_link_joint" type="fixed">
        <parent link="wheeltec_gripper_base_link"/>
        <child link="wheeltec_gripper_chaise"/>
        <origin xyz="-0.005 0 0.0272" rpy="0 ${-pi/2} 0"/>
    </joint>
 <link name="wheeltec_gripper_chaise">
    <inertial>
      <origin
        xyz="0.0293534223009873 0.0090853921588317 0.0106597454256406"
        rpy="0 0 0" />
      <mass
        value="0.102600550272344" />
      <inertia
        ixx="5.20788240164367E-05"
        ixy="6.54090863453443E-09"
        ixz="4.42197949237897E-10"
        iyy="3.20696114264544E-05"
        iyz="-1.34739886846522E-06"
        izz="4.78657905498745E-05" />
    </inertial>
    <visual>
      <origin
        xyz="0 0 0"
        rpy="0 0 0" />
      <geometry>
        <mesh
          filename="package://wheeltec_gripper_description/meshes/gripperbase.STL" />
      </geometry>
      <material
        name="">
        <color
          rgba="0.792156862745098 0.819607843137255 0.933333333333333 1" />
      </material>
    </visual>
    <collision>
          <origin
        xyz="0.0293534223009873 0.0090853921588317 0.0106597454256406"
        rpy="0 0 0" />
            <geometry>
                <box size="0.05 0.08 0.045"/>
            </geometry>
    </collision>
 </link>
  <gazebo reference="wheeltec_gripper_chaise">
    <material>Gazebo/Yellow</material>
  </gazebo>
  <!-- right_finger finger -->
  <joint name="left_finger_joint" type="revolute">
    <mimic joint="right_finger_joint"/>
    <origin xyz="0.071508 -0.024545 -0.020131"
      rpy="0 0 0" />
    <parent link="wheeltec_gripper_chaise"/>
    <child link="left_finger"/>
    <axis  xyz="2.5729E-05 -0.080001 0.99679"/>
    <limit  lower="0" upper="0.7298" effort="10"  velocity="1.0" />
    <dynamics damping="1" friction="1"/>
  </joint>
   <link
    name="left_finger">
    <inertial>
      <origin
        xyz="0.0324201926836488 -0.0145963763975525 0.0293610241174507"
        rpy="0 0 0" />
      <mass
        value="0.0454654477917792" />
      <inertia
        ixx="8.54538343821676E-06"
        ixy="9.08652805486317E-06"
        ixz="7.29792995722946E-07"
        iyy="2.33471912608672E-05"
        iyz="-4.42703368456901E-07"
        izz="2.88247074076199E-05" />
    </inertial>
    <visual>
      <origin
        xyz="0 0 0"
        rpy="0 0 0" />
      <geometry>
        <mesh
          filename="package://wheeltec_gripper_description/meshes/fingers.STL" />
      </geometry>
      <material
        name="">
        <color
          rgba="0.792156862745098 0.819607843137255 0.933333333333333 1" />
      </material>
    </visual>
    <collision>
          <origin
        xyz="0.0324201926836488 -0.0145963763975525 0.0293610241174507"
        rpy="0 0 -0.6" />
            <geometry>
                <box size="0.1 0.02 0.04"/>
            </geometry>
      </collision>
  </link>
  <link
     name="wheeltec_gripper_center">
<!--       <visual>
          <origin
        xyz="0 0 0"
        rpy="0 0 0" />
            <geometry>
                <box size="0.03 0.03 0.03"/>
            </geometry>
      </visual> -->
  </link>
  <joint name="wheeltec_gripper_center_joint" type="fixed">
    <origin xyz="0.125 0 0"
      rpy="0 0 0" />
    <parent link="wheeltec_gripper_chaise"/>
    <child link="wheeltec_gripper_center"/>
    <axis  xyz="0.125 0 0"/>
  </joint>

  <gazebo reference="left_finger">
    <material>Gazebo/Green</material>
  </gazebo>
  <xacro:macro name="transmission_macro" params="joint_name hardware_interface">
  <transmission name="trans_'${joint_name}'">
    <type>transmission_interface/SimpleTransmission</type>
    <joint name="left_finger_joint">
      <hardwareInterface>hardware_interface/${hardware_interface}</hardwareInterface>
    </joint>
    <actuator name="motor_left_finger_joint">
      <mechanicalReduction>1</mechanicalReduction>
      <hardwareInterface>hardware_interface/${hardware_interface}</hardwareInterface>
    </actuator>
  </transmission>
  </xacro:macro>
  <xacro:transmission_macro  joint_name="left_finger_joint" hardware_interface="PositionJointInterface"/>

  <!-- left_finger finger -->
  <joint name="right_finger_joint" type="revolute">
    <origin xyz="0.071485 0.047224 -0.01437"
      rpy="0 0 0.7298" />
    <parent link="wheeltec_gripper_chaise"/>
    <child link="right_finger"/>
    <axis xyz="-2.5729E-05 0.080001 -0.99679"/>
    <limit lower="0" upper="0.7298" effort="10"  velocity="1.0" />
    <mimic joint="left_finger_joint" multiplier="1" offset="0"/>
    <dynamics damping="1" friction="1"/>
  </joint>
   <link
    name="right_finger">
    <inertial>
      <origin
        xyz="0.0338378772194818 0.00534175148012631 0.0260745753522557"
        rpy="0 0 0" />
      <mass
        value="0.0454654472444149" />
      <inertia
        ixx="6.25574496069598E-06"
        ixy="-6.61546951322458E-06"
        ixz="-5.30362302163462E-07"
        iyy="2.5622104774585E-05"
        iyz="-2.59716886842376E-07"
        izz="2.88394198458503E-05" />
    </inertial>
    <visual>
      <origin
        xyz="0 0 0"
        rpy="0 0 0" />
      <geometry>
        <mesh
          filename="package://wheeltec_gripper_description/meshes/fingers.STL" />
      </geometry>
      <material
        name="">
        <color
          rgba="0.792156862745098 0.819607843137255 0.933333333333333 1" />
      </material>
    </visual>
    <collision>
          <origin
        xyz="0.0338378772194818 -0.02034175148012631 0.020745753522557"
        rpy="0 0 -0.3" />
            <geometry>
                <box size="0.1 0.02 0.04"/>
            </geometry>
      </collision>
  </link>
  <gazebo reference="right_finger">
    <material>Gazebo/Red</material>
  </gazebo>
<joint name="left_finger_joint">
  <param name="mimic">right_finger_joint</param>
  <param name="multiplier">1</param>
  <command_interface name="position"/>
  <state_interface name="position"/>
  <state_interface name="velocity"/>
  <state_interface name="effort"/>
</joint>
    <!-- ros_control plugin -->
    <gazebo>
      <plugin filename="gz_ros2_control-system" name="gz_ros2_control::GazeboSimROS2ControlPlugin">
        <parameters>$(find wheeltec_hardware_interface)/config/controllers.yaml</parameters>
      </plugin>
    </gazebo>

 <plugin filename="libgazebo_ros2_control.so" name="gazebo_ros2_control">
</plugin>
</robot>