<?xml version="1.0" ?>
<!-- =================================================================================== -->
<!-- |    This document was autogenerated by xacro from ar_gazebo.urdf.xacro           | -->
<!-- |    EDITING THIS FILE BY HAND IS NOT RECOMMENDED                                 | -->
<!-- =================================================================================== -->
<robot name="ar4">
  <link name="world"/>
  <joint name="base_joint" type="fixed">
    <origin rpy="0 0 0" xyz="0 0 0"/>
    <parent link="world"/>
    <child link="base_link"/>
  </joint>
  <link name="base_link">
    <inertial>
      <origin rpy="0 0 0" xyz="-4.6941E-06 0.054174 0.038824"/>
      <mass value="0.7102"/>
      <inertia ixx="0.0039943" ixy="3.697E-07" ixz="-5.7364E-08" iyy="0.0014946" iyz="-0.00036051" izz="0.0042554"/>
    </inertial>
    <visual>
      <origin rpy="0 0 0" xyz="0 0 0"/>
      <geometry>
        <mesh filename="file:///workspaces/ar4_ws/install/ar_description/share/ar_description/meshes/ar4/base_link.STL"/>
      </geometry>
      <material name="">
        <color rgba="1 1 0 1"/>
      </material>
    </visual>
    <collision>
      <origin rpy="0 0 0" xyz="0 0 0"/>
      <geometry>
        <mesh filename="file:///workspaces/ar4_ws/install/ar_description/share/ar_description/meshes/ar4/base_link.STL"/>
      </geometry>
    </collision>
  </link>
  <link name="link_1">
    <inertial>
      <origin rpy="0 0 0" xyz="-0.022706 0.04294 -0.12205"/>
      <mass value="0.88065"/>
      <inertia ixx="0.0034" ixy="0.00042296" ixz="-0.00089231" iyy="0.0041778" iyz="0.0010848" izz="0.0027077"/>
    </inertial>
    <visual>
      <origin rpy="0 0 0" xyz="0 0 0"/>
      <geometry>
        <mesh filename="file:///workspaces/ar4_ws/install/ar_description/share/ar_description/meshes/ar4/link_1.STL"/>
      </geometry>
      <material name="">
        <color rgba="1 1 0 1"/>
      </material>
    </visual>
    <collision>
      <origin rpy="0 0 0" xyz="0 0 0"/>
      <geometry>
        <mesh filename="file:///workspaces/ar4_ws/install/ar_description/share/ar_description/meshes/ar4/link_1.STL"/>
      </geometry>
    </collision>
  </link>
  <joint name="joint_1" type="revolute">
    <origin rpy="3.141592653589793 0 0" xyz="0 0 0"/>
    <parent link="base_link"/>
    <child link="link_1"/>
    <axis xyz="0 0 1"/>
    <limit effort="0" lower="-2.96705972839036" upper="2.96705972839036" velocity="0.5"/>
  </joint>
  <link name="link_2">
    <inertial>
      <origin rpy="0 0 0" xyz="0.064818 -0.11189 -0.038671"/>
      <mass value="0.57738"/>
      <inertia ixx="0.0047312" ixy="0.0022624" ixz="0.00032144" iyy="0.0020836" iyz="-0.00056569" izz="0.0056129"/>
    </inertial>
    <visual>
      <origin rpy="0 0 0" xyz="0 0 0"/>
      <geometry>
        <mesh filename="file:///workspaces/ar4_ws/install/ar_description/share/ar_description/meshes/ar4/link_2.STL"/>
      </geometry>
      <material name="">
        <color rgba="1 1 0 1"/>
      </material>
    </visual>
    <collision>
      <origin rpy="0 0 0" xyz="0 0 0"/>
      <geometry>
        <mesh filename="file:///workspaces/ar4_ws/install/ar_description/share/ar_description/meshes/ar4/link_2.STL"/>
      </geometry>
    </collision>
  </link>
  <joint name="joint_2" type="revolute">
    <origin rpy="1.5708 0 -1.5708" xyz="0 0.0642 -0.16977"/>
    <parent link="link_1"/>
    <child link="link_2"/>
    <axis xyz="0 0 -1"/>
    <limit effort="0.5" lower="-0.7330382858376184" upper="1.5707963267948966" velocity="0.5"/>
  </joint>
  <link name="link_3">
    <inertial>
      <origin rpy="0 0 0" xyz="-0.00029765 -0.023661 -0.0019125"/>
      <mass value="0.1787"/>
      <inertia ixx="0.0001685" ixy="-2.7713E-05" ixz="5.6885E-06" iyy="0.00012865" iyz="2.9256E-05" izz="0.00020744"/>
    </inertial>
    <visual>
      <origin rpy="0 0 0" xyz="0 0 0"/>
      <geometry>
        <mesh filename="file:///workspaces/ar4_ws/install/ar_description/share/ar_description/meshes/ar4/link_3.STL"/>
      </geometry>
      <material name="">
        <color rgba="1 1 0 1"/>
      </material>
    </visual>
    <collision>
      <origin rpy="0 0 0" xyz="0 0 0"/>
      <geometry>
        <mesh filename="file:///workspaces/ar4_ws/install/ar_description/share/ar_description/meshes/ar4/link_3.STL"/>
      </geometry>
    </collision>
  </link>
  <joint name="joint_3" type="revolute">
    <origin rpy="0 0 3.1416" xyz="0 -0.305 0.007"/>
    <parent link="link_2"/>
    <child link="link_3"/>
    <axis xyz="0 0 -1"/>
    <limit effort="0" lower="-1.5533430342749532" upper="0.9075712110370513" velocity="0.5"/>
  </joint>
  <link name="link_4">
    <inertial>
      <origin rpy="0 0 0" xyz="-0.0016798 -0.00057319 -0.074404"/>
      <mass value="0.34936"/>
      <inertia ixx="0.0030532" ixy="-1.8615E-05" ixz="-7.0047E-05" iyy="0.0031033" iyz="-2.3301E-05" izz="0.00022264"/>
    </inertial>
    <visual>
      <origin rpy="0 0 0" xyz="0 0 0"/>
      <geometry>
        <mesh filename="file:///workspaces/ar4_ws/install/ar_description/share/ar_description/meshes/ar4/link_4.STL"/>
      </geometry>
      <material name="">
        <color rgba="1 1 0 1"/>
      </material>
    </visual>
    <collision>
      <origin rpy="0 0 0" xyz="0 0 0"/>
      <geometry>
        <mesh filename="file:///workspaces/ar4_ws/install/ar_description/share/ar_description/meshes/ar4/link_4.STL"/>
      </geometry>
    </collision>
  </link>
  <joint name="joint_4" type="revolute">
    <origin rpy="1.5708 0 -1.5708" xyz="0 0 0.0"/>
    <parent link="link_3"/>
    <child link="link_4"/>
    <axis xyz="0 0 -1"/>
    <limit effort="0" lower="-2.8797932657906435" upper="2.8797932657906435" velocity="0.5"/>
  </joint>
  <link name="link_5">
    <inertial>
      <origin rpy="0 0 0" xyz="0.0015066 -1.3102E-05 -0.012585"/>
      <mass value="0.11562"/>
      <inertia ixx="5.5035E-05" ixy="-1.019E-08" ixz="-2.6243E-06" iyy="8.2921E-05" iyz="1.4437E-08" izz="5.2518E-05"/>
    </inertial>
    <visual>
      <origin rpy="0 0 0" xyz="0 0 0"/>
      <geometry>
        <mesh filename="file:///workspaces/ar4_ws/install/ar_description/share/ar_description/meshes/ar4/link_5.STL"/>
      </geometry>
      <material name="">
        <color rgba="1 1 0 1"/>
      </material>
    </visual>
    <collision>
      <origin rpy="0 0 0" xyz="0 0 0"/>
      <geometry>
        <mesh filename="file:///workspaces/ar4_ws/install/ar_description/share/ar_description/meshes/ar4/link_5.STL"/>
      </geometry>
    </collision>
  </link>
  <joint name="joint_5" type="revolute">
    <origin rpy="3.141592653589793 0 -1.5708" xyz="0 0 -0.22263"/>
    <parent link="link_4"/>
    <child link="link_5"/>
    <axis xyz="1 0 0"/>
    <limit effort="0" lower="-1.8325957145940461" upper="1.8325957145940461" velocity="1.0"/>
  </joint>
  <link name="link_6">
    <inertial>
      <origin rpy="0 0 0" xyz="2.9287E-10 -1.6472E-09 0.0091432"/>
      <mass value="0.013863"/>
      <inertia ixx="1.3596E-06" ixy="3.0585E-13" ixz="5.7102E-14" iyy="1.7157E-06" iyz="6.3369E-09" izz="2.4332E-06"/>
    </inertial>
    <visual>
      <origin rpy="0 0 0" xyz="0 0 0"/>
      <geometry>
        <mesh filename="file:///workspaces/ar4_ws/install/ar_description/share/ar_description/meshes/ar4/link_6.STL"/>
      </geometry>
      <material name="">
        <color rgba="1 1 0 1"/>
      </material>
    </visual>
    <collision>
      <origin rpy="0 0 0" xyz="0 0 0"/>
      <geometry>
        <mesh filename="file:///workspaces/ar4_ws/install/ar_description/share/ar_description/meshes/ar4/link_6.STL"/>
      </geometry>
    </collision>
  </link>
  <joint name="joint_6" type="revolute">
    <origin rpy="0 0 3.1416" xyz="0.000 0 0.03625"/>
    <parent link="link_5"/>
    <child link="link_6"/>
    <axis xyz="0 0 1"/>
    <limit effort="0" lower="-2.705260340591211" upper="2.705260340591211" velocity="1.0"/>
  </joint>
  <!-- center of the end effector mounting surface on link_6 -->
  <link name="ee_link"/>
  <joint name="ee_joint" type="fixed">
    <parent link="link_6"/>
    <child link="ee_link"/>
    <origin rpy="0 0 0" xyz="0 0 0.0"/>
  </joint>
  <link name="wheeltec_gripper_base_link"/>
  <joint name="wheeltec_gripper_base_link_joint" type="fixed">
    <parent link="wheeltec_gripper_base_link"/>
    <child link="wheeltec_gripper_chaise"/>
    <origin rpy="0 -1.5707963267948966 0" xyz="-0.005 0 0.0272"/>
  </joint>
  <link name="wheeltec_gripper_chaise">
    <inertial>
      <origin rpy="0 0 0" xyz="0.0293534223009873 0.0090853921588317 0.0106597454256406"/>
      <mass value="0.102600550272344"/>
      <inertia ixx="5.20788240164367E-05" ixy="6.54090863453443E-09" ixz="4.42197949237897E-10" iyy="3.20696114264544E-05" iyz="-1.34739886846522E-06" izz="4.78657905498745E-05"/>
    </inertial>
    <visual>
      <origin rpy="0 0 0" xyz="0 0 0"/>
      <geometry>
        <mesh filename="package://wheeltec_gripper_description/meshes/gripperbase.STL"/>
      </geometry>
      <material name="">
        <color rgba="0.792156862745098 0.819607843137255 0.933333333333333 1"/>
      </material>
    </visual>
    <collision>
      <origin rpy="0 0 0" xyz="0.0293534223009873 0.0090853921588317 0.0106597454256406"/>
      <geometry>
        <box size="0.05 0.08 0.045"/>
      </geometry>
    </collision>
  </link>
  <gazebo reference="wheeltec_gripper_chaise">
    <material>Gazebo/Yellow</material>
  </gazebo>
  <!-- right_finger finger -->
  <joint name="left_finger_joint" type="revolute">
    <mimic joint="right_finger_joint"/>
    <origin rpy="0 0 0" xyz="0.071508 -0.024545 -0.020131"/>
    <parent link="wheeltec_gripper_chaise"/>
    <child link="left_finger"/>
    <axis xyz="2.5729E-05 -0.080001 0.99679"/>
    <limit effort="10" lower="0" upper="0.7298" velocity="1.0"/>
    <dynamics damping="1" friction="1"/>
  </joint>
  <link name="left_finger">
    <inertial>
      <origin rpy="0 0 0" xyz="0.0324201926836488 -0.0145963763975525 0.0293610241174507"/>
      <mass value="0.0454654477917792"/>
      <inertia ixx="8.54538343821676E-06" ixy="9.08652805486317E-06" ixz="7.29792995722946E-07" iyy="2.33471912608672E-05" iyz="-4.42703368456901E-07" izz="2.88247074076199E-05"/>
    </inertial>
    <visual>
      <origin rpy="0 0 0" xyz="0 0 0"/>
      <geometry>
        <mesh filename="package://wheeltec_gripper_description/meshes/fingers.STL"/>
      </geometry>
      <material name="">
        <color rgba="0.792156862745098 0.819607843137255 0.933333333333333 1"/>
      </material>
    </visual>
    <collision>
      <origin rpy="0 0 -0.6" xyz="0.0324201926836488 -0.0145963763975525 0.0293610241174507"/>
      <geometry>
        <box size="0.1 0.02 0.04"/>
      </geometry>
    </collision>
  </link>
  <link name="wheeltec_gripper_center">
    <!--       <visual>
          <origin
        xyz="0 0 0"
        rpy="0 0 0" />
            <geometry>
                <box size="0.03 0.03 0.03"/>
            </geometry>
      </visual> -->
  </link>
  <joint name="wheeltec_gripper_center_joint" type="fixed">
    <origin rpy="0 0 0" xyz="0.125 0 0"/>
    <parent link="wheeltec_gripper_chaise"/>
    <child link="wheeltec_gripper_center"/>
    <axis xyz="0.125 0 0"/>
  </joint>
  <gazebo reference="left_finger">
    <material>Gazebo/Green</material>
  </gazebo>
  <transmission name="trans_'left_finger_joint'">
    <type>transmission_interface/SimpleTransmission</type>
    <joint name="left_finger_joint">
      <hardwareInterface>hardware_interface/PositionJointInterface</hardwareInterface>
    </joint>
    <actuator name="motor_left_finger_joint">
      <mechanicalReduction>1</mechanicalReduction>
      <hardwareInterface>hardware_interface/PositionJointInterface</hardwareInterface>
    </actuator>
  </transmission>
  <!-- left_finger finger -->
  <joint name="right_finger_joint" type="revolute">
    <origin rpy="0 0 0.7298" xyz="0.071485 0.047224 -0.01437"/>
    <parent link="wheeltec_gripper_chaise"/>
    <child link="right_finger"/>
    <axis xyz="-2.5729E-05 0.080001 -0.99679"/>
    <limit effort="10" lower="0" upper="0.7298" velocity="1.0"/>
    <mimic joint="left_finger_joint" multiplier="1" offset="0"/>
    <dynamics damping="1" friction="1"/>
  </joint>
  <link name="right_finger">
    <inertial>
      <origin rpy="0 0 0" xyz="0.0338378772194818 0.00534175148012631 0.0260745753522557"/>
      <mass value="0.0454654472444149"/>
      <inertia ixx="6.25574496069598E-06" ixy="-6.61546951322458E-06" ixz="-5.30362302163462E-07" iyy="2.5622104774585E-05" iyz="-2.59716886842376E-07" izz="2.88394198458503E-05"/>
    </inertial>
    <visual>
      <origin rpy="0 0 0" xyz="0 0 0"/>
      <geometry>
        <mesh filename="package://wheeltec_gripper_description/meshes/fingers.STL"/>
      </geometry>
      <material name="">
        <color rgba="0.792156862745098 0.819607843137255 0.933333333333333 1"/>
      </material>
    </visual>
    <collision>
      <origin rpy="0 0 -0.3" xyz="0.0338378772194818 -0.02034175148012631 0.020745753522557"/>
      <geometry>
        <box size="0.1 0.02 0.04"/>
      </geometry>
    </collision>
  </link>
  <gazebo reference="right_finger">
    <material>Gazebo/Red</material>
  </gazebo>
  <ros2_control name="ARGazeboSystem" type="system">
    <hardware>
      <plugin>gazebo_ros2_control/GazeboSystem</plugin>
      <param name="serial_port">None</param>
      <param name="calibrate">False</param>
    </hardware>
    <joint name="joint_1">
      <command_interface name="position">
        <param name="min">{-170*pi/180}</param>
        <param name="max">{170*pi/180}</param>
      </command_interface>
      <state_interface name="position">
        <param name="initial_value">0.0</param>
      </state_interface>
      <param name="position_offset">170.0</param>
    </joint>
    <joint name="joint_2">
      <command_interface name="position">
        <param name="min">{-42*pi/180}</param>
        <param name="max">{90*pi/180}</param>
      </command_interface>
      <state_interface name="position">
        <param name="initial_value">0.0</param>
      </state_interface>
      <param name="position_offset">-42.0</param>
    </joint>
    <joint name="joint_3">
      <command_interface name="position">
        <param name="min">{-89*pi/180}</param>
        <param name="max">{52*pi/180}</param>
      </command_interface>
      <state_interface name="position">
        <param name="initial_value">0.0</param>
      </state_interface>
      <param name="position_offset">-89.0</param>
    </joint>
    <joint name="joint_4">
      <command_interface name="position">
        <param name="min">{-165*pi/180}</param>
        <param name="max">{165*pi/180}</param>
      </command_interface>
      <state_interface name="position">
        <param name="initial_value">0.0</param>
      </state_interface>
      <param name="position_offset">-165.0</param>
    </joint>
    <joint name="joint_5">
      <command_interface name="position">
        <param name="min">{-105*pi/180}</param>
        <param name="max">{105*pi/180}</param>
      </command_interface>
      <state_interface name="position">
        <param name="initial_value">0.0</param>
      </state_interface>
      <param name="position_offset">-105.0</param>
    </joint>
    <joint name="joint_6">
      <command_interface name="position">
        <param name="min">{-155*pi/180}</param>
        <param name="max">{155*pi/180}</param>
      </command_interface>
      <state_interface name="position">
        <param name="initial_value">0.0</param>
      </state_interface>
      <param name="position_offset">-155.0</param>
    </joint>
  </ros2_control>
  <ros2_control name="ARGripperGazeboSystem" type="system">
    <hardware>
      <plugin>gazebo_ros2_control/GazeboSystem</plugin>
      <param name="serial_port">None</param>
    </hardware>
    <joint name="left_finger_joint">
      <command_interface name="position"/>
      <state_interface name="position">
        <param name="initial_value">0.0</param>
      </state_interface>
      <state_interface name="velocity">
        <param name="initial_value">0.0</param>
      </state_interface>
    </joint>
    <joint name="right_finger_joint">
      <param name="mimic">left_finger_joint</param>
      <param name="multiplier">1</param>
      <command_interface name="position"/>
      <state_interface name="position">
        <param name="initial_value">0.0</param>
      </state_interface>
      <state_interface name="velocity">
        <param name="initial_value">0.0</param>
      </state_interface>
    </joint>
  </ros2_control>
  <gazebo reference="world"/>
  <gazebo>
    <plugin filename="libgazebo_ros2_control.so" name="gazebo_ros2_control">
      <parameters></parameters>
    </plugin>
  </gazebo>
</robot>